While executing file `Games/Thumgeon_II/main.py` an error occurred (<module> refers to the game file):

Traceback (most recent call last):
  File "launcher.py", line 307, in <module>
  File "main.py", line 34, in <module>
  File "/home/devy/Desktop/micropython-rp2350-1.22.0-engine/examples/usercmodule/TinyCircuits-Tiny-Game-Engine/filesystem/Games/Thumgeon_II/Render.py", line 11, in <module>
  File "/home/devy/Desktop/micropython-rp2350-1.22.0-engine/examples/usercmodule/TinyCircuits-Tiny-Game-Engine/filesystem/Games/Thumgeon_II/Player.py", line 18, in <module>
ValueError: I/O operation on closed file
